<?xml version="1.0" ?>
<!-- =================================================================================== -->
<!-- |    This document was autogenerated by xacro from /home/zf/Documents/ROS/catkin_ws/src/universal_robot/ur_description/urdf/ur3_ft_gripper_realsense.xacro | -->
<!-- |    EDITING THIS FILE BY HAND IS NOT RECOMMENDED                                 | -->
<!-- =================================================================================== -->
<robot name="ur3_robot_ft_gripper">
    <!--
    Base UR robot series xacro macro.

    NOTE: this is NOT a URDF. It cannot directly be loaded by consumers
    expecting a flattened '.urdf' file. See the top-level '.xacro' for that
    (but note: that .xacro must still be processed by the xacro command).

    For use in '.launch' files: use one of the 'load_urX.launch' convenience
    launch files.

    This file models the base kinematic chain of a UR robot, which then gets
    parameterised by various configuration files to convert it into a UR3(e),
    UR5(e), UR10(e) or UR16e.

    NOTE: the default kinematic parameters (ie: link lengths, frame locations,
    offets, etc) do not correspond to any particular robot. They are defaults
    only. There WILL be non-zero offsets between the Forward Kinematics results
    in TF (ie: robot_state_publisher) and the values reported by the Teach
    Pendant.

    For accurate (and robot-specific) transforms, the 'kinematics_parameters_file'
    parameter MUST point to a .yaml file containing the appropriate values for
    the targetted robot.

    If using the UniversalRobots/Universal_Robots_ROS_Driver, follow the steps
    described in the readme of that repository to extract the kinematic
    calibration from the controller and generate the required .yaml file.

    Main author of the migration to yaml configs: Ludovic Delval.

    Contributors to previous versions (in no particular order):

     - Felix Messmer
     - Kelsey Hawkins
     - Wim Meeussen
     - Shaun Edwards
     - Nadia Hammoudeh Garcia
     - Dave Hershberger
     - G. vd. Hoorn
     - Philip Long
     - Dave Coleman
     - Miguel Prada
     - Mathias Luedtke
     - Marcel Schnirring
     - Felix von Drigalski
     - Felix Exner
     - Jimmy Da Silva
     - Ajit Krisshna N L
     - Muhammad Asif Rana
  -->
    <!--
    NOTE: the macro defined in this file is NOT part of the public API of this
          package. Users CANNOT rely on this file being available, or stored in
          this location. Nor can they rely on the existence of the macro.
  -->
    <transmission name="shoulder_pan_trans">
        <type>transmission_interface/SimpleTransmission</type>
        <joint name="shoulder_pan_joint">
            <hardwareInterface>hardware_interface/PositionJointInterface</hardwareInterface>
        </joint>
        <actuator name="shoulder_pan_motor">
            <mechanicalReduction>1</mechanicalReduction>
            <hardwareInterface>hardware_interface/EffortJointInterface</hardwareInterface>
        </actuator>
    </transmission>
    <transmission name="shoulder_lift_trans">
        <type>transmission_interface/SimpleTransmission</type>
        <joint name="shoulder_lift_joint">
            <hardwareInterface>hardware_interface/PositionJointInterface</hardwareInterface>
        </joint>
        <actuator name="shoulder_lift_motor">
            <mechanicalReduction>1</mechanicalReduction>
            <hardwareInterface>hardware_interface/EffortJointInterface</hardwareInterface>
        </actuator>
    </transmission>
    <transmission name="elbow_trans">
        <type>transmission_interface/SimpleTransmission</type>
        <joint name="elbow_joint">
            <hardwareInterface>hardware_interface/PositionJointInterface</hardwareInterface>
        </joint>
        <actuator name="elbow_motor">
            <mechanicalReduction>1</mechanicalReduction>
            <hardwareInterface>hardware_interface/EffortJointInterface</hardwareInterface>
        </actuator>
    </transmission>
    <transmission name="wrist_1_trans">
        <type>transmission_interface/SimpleTransmission</type>
        <joint name="wrist_1_joint">
            <hardwareInterface>hardware_interface/PositionJointInterface</hardwareInterface>
        </joint>
        <actuator name="wrist_1_motor">
            <mechanicalReduction>1</mechanicalReduction>
            <hardwareInterface>hardware_interface/EffortJointInterface</hardwareInterface>
        </actuator>
    </transmission>
    <transmission name="wrist_2_trans">
        <type>transmission_interface/SimpleTransmission</type>
        <joint name="wrist_2_joint">
            <hardwareInterface>hardware_interface/PositionJointInterface</hardwareInterface>
        </joint>
        <actuator name="wrist_2_motor">
            <mechanicalReduction>1</mechanicalReduction>
            <hardwareInterface>hardware_interface/EffortJointInterface</hardwareInterface>
        </actuator>
    </transmission>
    <transmission name="wrist_3_trans">
        <type>transmission_interface/SimpleTransmission</type>
        <joint name="wrist_3_joint">
            <hardwareInterface>hardware_interface/PositionJointInterface</hardwareInterface>
        </joint>
        <actuator name="wrist_3_motor">
            <mechanicalReduction>1</mechanicalReduction>
            <hardwareInterface>hardware_interface/EffortJointInterface</hardwareInterface>
        </actuator>
    </transmission>
    <!-- links: main serial chain -->
    <link name="base_link" />
    <link name="base_link_inertia">
        <visual>
            <origin rpy="0 0 3.141592653589793" xyz="0 0 0" />
            <geometry>
                <mesh filename="package://ur_description/meshes/ur3/visual/base.dae" />
            </geometry>
            <material name="LightGrey">
                <color rgba="0.7 0.7 0.7 1.0" />
            </material>
        </visual>
        <collision>
            <origin rpy="0 0 3.141592653589793" xyz="0 0 0" />
            <geometry>
                <mesh filename="package://ur_description/meshes/ur3/collision/base.stl" />
            </geometry>
        </collision>
        <inertial>
            <mass value="2.0" />
            <origin rpy="0 0 0" xyz="0 0 0" />
            <inertia ixx="0.0030531654454" ixy="0.0" ixz="0.0" iyy="0.0030531654454" iyz="0.0" izz="0.005625" />
        </inertial>
    </link>
    <link name="shoulder_link">
        <visual>
            <origin rpy="0 0 3.141592653589793" xyz="0 0 0" />
            <geometry>
                <mesh filename="package://ur_description/meshes/ur3/visual/shoulder.dae" />
            </geometry>
            <material name="LightGrey">
                <color rgba="0.7 0.7 0.7 1.0" />
            </material>
        </visual>
        <collision>
            <origin rpy="0 0 3.141592653589793" xyz="0 0 0" />
            <geometry>
                <mesh filename="package://ur_description/meshes/ur3/collision/shoulder.stl" />
            </geometry>
        </collision>
        <inertial>
            <mass value="2.0" />
            <origin rpy="0 0 0" xyz="0 0 0" />
            <inertia ixx="0.008093163429399999" ixy="0.0" ixz="0.0" iyy="0.008093163429399999" iyz="0.0" izz="0.005625" />
        </inertial>
    </link>
    <link name="upper_arm_link">
        <visual>
            <origin rpy="1.5707963267948966 0 -1.5707963267948966" xyz="0 0 0.1198" />
            <geometry>
                <mesh filename="package://ur_description/meshes/ur3/visual/upperarm.dae" />
            </geometry>
            <material name="LightGrey">
                <color rgba="0.7 0.7 0.7 1.0" />
            </material>
        </visual>
        <collision>
            <origin rpy="1.5707963267948966 0 -1.5707963267948966" xyz="0 0 0.1198" />
            <geometry>
                <mesh filename="package://ur_description/meshes/ur3/collision/upperarm.stl" />
            </geometry>
        </collision>
        <inertial>
            <mass value="3.42" />
            <origin rpy="0 1.5707963267948966 0" xyz="-0.121825 0.0 0.12" />
            <inertia ixx="0.021728483221103233" ixy="0.0" ixz="0.0" iyy="0.021728483221103233" iyz="0.0" izz="0.00961875" />
        </inertial>
    </link>
    <link name="forearm_link">
        <visual>
            <origin rpy="1.5707963267948966 0 -1.5707963267948966" xyz="0 0 0.0275" />
            <geometry>
                <mesh filename="package://ur_description/meshes/ur3/visual/forearm.dae" />
            </geometry>
            <material name="LightGrey">
                <color rgba="0.7 0.7 0.7 1.0" />
            </material>
        </visual>
        <collision>
            <origin rpy="1.5707963267948966 0 -1.5707963267948966" xyz="0 0 0.0275" />
            <geometry>
                <mesh filename="package://ur_description/meshes/ur3/collision/forearm.stl" />
            </geometry>
        </collision>
        <inertial>
            <mass value="1.26" />
            <origin rpy="0 1.5707963267948966 0" xyz="-0.106625 0.0 0.0275" />
            <inertia ixx="0.006546806443776375" ixy="0.0" ixz="0.0" iyy="0.006546806443776375" iyz="0.0" izz="0.00354375" />
        </inertial>
    </link>
    <link name="wrist_1_link">
        <visual>
            <!-- TODO: Move this to a parameter -->
            <origin rpy="1.5707963267948966 0 0" xyz="0 0 -0.085" />
            <geometry>
                <mesh filename="package://ur_description/meshes/ur3/visual/wrist1.dae" />
            </geometry>
            <material name="LightGrey">
                <color rgba="0.7 0.7 0.7 1.0" />
            </material>
        </visual>
        <collision>
            <origin rpy="1.5707963267948966 0 0" xyz="0 0 -0.085" />
            <geometry>
                <mesh filename="package://ur_description/meshes/ur3/collision/wrist1.stl" />
            </geometry>
        </collision>
        <inertial>
            <mass value="0.8" />
            <origin rpy="0 0 0" xyz="0 0 0" />
            <inertia ixx="0.0016106408557434" ixy="0.0" ixz="0.0" iyy="0.0016106408557434" iyz="0.0" izz="0.00225" />
        </inertial>
    </link>
    <link name="wrist_2_link">
        <visual>
            <origin rpy="0 0 0" xyz="0 0 -0.085" />
            <geometry>
                <mesh filename="package://ur_description/meshes/ur3/visual/wrist2.dae" />
            </geometry>
            <material name="LightGrey">
                <color rgba="0.7 0.7 0.7 1.0" />
            </material>
        </visual>
        <collision>
            <origin rpy="0 0 0" xyz="0 0 -0.085" />
            <geometry>
                <mesh filename="package://ur_description/meshes/ur3/collision/wrist2.stl" />
            </geometry>
        </collision>
        <inertial>
            <mass value="0.8" />
            <origin rpy="0 0 0" xyz="0 0 0" />
            <inertia ixx="0.0015721733711303997" ixy="0.0" ixz="0.0" iyy="0.0015721733711303997" iyz="0.0" izz="0.00225" />
        </inertial>
    </link>
    <link name="wrist_3_link">
        <visual>
            <origin rpy="1.5707963267948966 0 0" xyz="0 0 -0.082" />
            <geometry>
                <mesh filename="package://ur_description/meshes/ur3/visual/wrist3.dae" />
            </geometry>
            <material name="LightGrey">
                <color rgba="0.7 0.7 0.7 1.0" />
            </material>
        </visual>
        <collision>
            <origin rpy="1.5707963267948966 0 0" xyz="0 0 -0.082" />
            <geometry>
                <mesh filename="package://ur_description/meshes/ur3/collision/wrist3.stl" />
            </geometry>
        </collision>
        <inertial>
            <mass value="0.35" />
            <origin rpy="0 0 0" xyz="0.0 0.0 -0.02" />
            <inertia ixx="0.00013626661215999998" ixy="0.0" ixz="0.0" iyy="0.00013626661215999998" iyz="0.0" izz="0.0001792" />
        </inertial>
    </link>
    <!-- joints: main serial chain -->
    <joint name="base_link-base_link_inertia" type="fixed">
        <parent link="base_link" />
        <child link="base_link_inertia" />
        <!-- 'base_link' is REP-103 aligned (so X+ forward), while the internal
           frames of the robot/controller have X+ pointing backwards.
           Use the joint between 'base_link' and 'base_link_inertia' (a dummy
           link/frame) to introduce the necessary rotation over Z (of pi rad).
      -->
        <origin rpy="0 0 3.141592653589793" xyz="0 0 0" />
    </joint>
    <joint name="shoulder_pan_joint" type="revolute">
        <parent link="base_link_inertia" />
        <child link="shoulder_link" />
        <origin rpy="0 0 0" xyz="0 0 0.1519" />
        <axis xyz="0 0 1" />
        <limit effort="56.0" lower="-6.283185307179586" upper="6.283185307179586" velocity="3.141592653589793" />
        <dynamics damping="0" friction="0" />
    </joint>
    <joint name="shoulder_lift_joint" type="revolute">
        <parent link="shoulder_link" />
        <child link="upper_arm_link" />
        <origin rpy="1.570796327 0 0" xyz="0 0 0" />
        <axis xyz="0 0 1" />
        <limit effort="56.0" lower="-6.283185307179586" upper="6.283185307179586" velocity="3.141592653589793" />
        <dynamics damping="0" friction="0" />
    </joint>
    <joint name="elbow_joint" type="revolute">
        <parent link="upper_arm_link" />
        <child link="forearm_link" />
        <origin rpy="0 0 0" xyz="-0.24365 0 0" />
        <axis xyz="0 0 1" />
        <limit effort="28.0" lower="-3.141592653589793" upper="3.141592653589793" velocity="3.141592653589793" />
        <dynamics damping="0" friction="0" />
    </joint>
    <joint name="wrist_1_joint" type="revolute">
        <parent link="forearm_link" />
        <child link="wrist_1_link" />
        <origin rpy="0 0 0" xyz="-0.21325 0 0.11235" />
        <axis xyz="0 0 1" />
        <limit effort="12.0" lower="-6.283185307179586" upper="6.283185307179586" velocity="6.283185307179586" />
        <dynamics damping="0" friction="0" />
    </joint>
    <joint name="wrist_2_joint" type="revolute">
        <parent link="wrist_1_link" />
        <child link="wrist_2_link" />
        <origin rpy="1.570796327 0 0" xyz="0 -0.08535 -1.750557762378351e-11" />
        <axis xyz="0 0 1" />
        <limit effort="12.0" lower="-6.283185307179586" upper="6.283185307179586" velocity="6.283185307179586" />
        <dynamics damping="0" friction="0" />
    </joint>
    <joint name="wrist_3_joint" type="revolute">
        <parent link="wrist_2_link" />
        <child link="wrist_3_link" />
        <origin rpy="1.570796326589793 3.141592653589793 3.141592653589793" xyz="0 0.0819 -1.679797079540562e-11" />
        <axis xyz="0 0 1" />
        <limit effort="12.0" lower="-6.283185307179586" upper="6.283185307179586" velocity="6.283185307179586" />
        <dynamics damping="0" friction="0" />
    </joint>
    <!-- ROS-Industrial 'base' frame: base_link to UR 'Base' Coordinates transform -->
    <link name="base" />
    <joint name="base_link-base_fixed_joint" type="fixed">
        <!-- Note the rotation over Z of pi radians: as base_link is REP-103
           aligned (ie: has X+ forward, Y+ left and Z+ up), this is needed
           to correctly align 'base' with the 'Base' coordinate system of
           the UR controller.
      -->
        <origin rpy="0 0 3.141592653589793" xyz="0 0 0" />
        <parent link="base_link" />
        <child link="base" />
    </joint>
    <!-- ROS-Industrial 'flange' frame: attachment point for EEF models -->
    <link name="flange" />
    <joint name="wrist_3-flange" type="fixed">
        <parent link="wrist_3_link" />
        <child link="flange" />
        <origin rpy="0 -1.5707963267948966 -1.5707963267948966" xyz="0 0 0" />
    </joint>
    <!-- ROS-Industrial 'tool0' frame: all-zeros tool frame -->
    <link name="tool0" />
    <joint name="flange-tool0" type="fixed">
        <!-- default toolframe: X+ left, Y+ up, Z+ front -->
        <origin rpy="1.5707963267948966 0 1.5707963267948966" xyz="0 0 0" />
        <parent link="flange" />
        <child link="tool0" />
    </joint>
    <transmission name="finger_joint_trans">
        <type>transmission_interface/SimpleTransmission</type>
        <joint name="finger_joint">
            <hardwareInterface>hardware_interface/EffortJointInterface</hardwareInterface>
        </joint>
        <actuator name="finger_joint_motor">
            <mechanicalReduction>1</mechanicalReduction>
            <hardwareInterface>hardware_interface/EffortJointInterface</hardwareInterface>
        </actuator>
    </transmission>
    <!-- base link -->
    <!-- 将gripper固定在sensor上而不是在base_link上 -->
    <!-- <link name="${prefix}base_link"/>
    <joint name="${prefix}base_link-${prefix}robotiq_arg2f_base_link" type="fixed">
      <parent link="${prefix}base_link" />
      <child link="${prefix}robotiq_arg2f_base_link" />
    </joint> -->
    <link name="robotiq_arg2f_base_link">
        <inertial>
            <origin rpy="0 0 0" xyz="8.625E-08 -4.6583E-06 0.03145" />
            <mass value="0.22652" />
            <inertia ixx="0.00020005" ixy="-4.2442E-10" ixz="-2.9069E-10" iyy="0.00017832" iyz="-3.4402E-08" izz="0.00013478" />
        </inertial>
        <visual>
            <origin rpy="0 0 0" xyz="0 0 0" />
            <geometry>
                <mesh filename="package://robotiq_2f_140_gripper_visualization/meshes/visual/robotiq_arg2f_base_link.stl" />
            </geometry>
            <material name="">
                <color rgba="0.1 0.1 0.1 1" />
            </material>
        </visual>
        <collision>
            <origin rpy="0 0 0" xyz="0 0 0" />
            <geometry>
                <mesh filename="package://robotiq_2f_140_gripper_visualization/meshes/collision/robotiq_arg2f_base_link.stl" />
            </geometry>
        </collision>
    </link>
    <link name="left_outer_knuckle">
        <inertial>
            <origin rpy="0 0 0" xyz="-0.000200000000003065 0.0199435877845359 0.0292245259211331" />
            <mass value="0.00853198276973456" />
            <inertia ixx="2.89328108496468E-06" ixy="-1.57935047237397E-19" ixz="-1.93980378593255E-19" iyy="1.86719750325683E-06" iyz="-1.21858577871576E-06" izz="1.21905238907251E-06" />
        </inertial>
        <visual>
            <origin rpy="0 0 0" xyz="0 0 0" />
            <geometry>
                <mesh filename="package://robotiq_2f_140_gripper_visualization/meshes/visual/robotiq_arg2f_140_outer_knuckle.stl" />
            </geometry>
            <material name="">
                <color rgba="0.792156862745098 0.819607843137255 0.933333333333333 1" />
            </material>
        </visual>
        <collision>
            <origin rpy="0 0 0" xyz="0 0 0" />
            <geometry>
                <mesh filename="package://robotiq_2f_140_gripper_visualization/meshes/collision/robotiq_arg2f_140_outer_knuckle.stl" />
            </geometry>
        </collision>
    </link>
    <link name="left_outer_finger">
        <inertial>
            <origin rpy="0 0 0" xyz="0.00030115855001899 0.0373907951953854 -0.0208027427000385" />
            <mass value="0.022614240507152" />
            <inertia ixx="1.52518312458174E-05" ixy="9.76583423954399E-10" ixz="-5.43838577022588E-10" iyy="6.17694243867776E-06" iyz="6.78636130740228E-06" izz="1.16494917907219E-05" />
        </inertial>
        <visual>
            <origin rpy="0 0 0" xyz="0 0 0" />
            <geometry>
                <mesh filename="package://robotiq_2f_140_gripper_visualization/meshes/visual/robotiq_arg2f_140_outer_finger.stl" />
            </geometry>
            <material name="">
                <color rgba="0.1 0.1 0.1 1" />
            </material>
        </visual>
        <collision>
            <origin rpy="0 0 0" xyz="0 0 0" />
            <geometry>
                <mesh filename="package://robotiq_2f_140_gripper_visualization/meshes/collision/robotiq_arg2f_140_outer_finger.stl" />
            </geometry>
        </collision>
    </link>
    <link name="left_inner_finger">
        <inertial>
            <origin rpy="0 0 0" xyz="0.000299999999999317 0.0160078233491243 -0.0136945669206257" />
            <mass value="0.0104003125914103" />
            <inertia ixx="2.71909453810972E-06" ixy="1.35402465472579E-21" ixz="-7.1817349065269E-22" iyy="7.69100314106116E-07" iyz="6.74715432769696E-07" izz="2.30315190420171E-06" />
        </inertial>
        <visual>
            <origin rpy="0 0 0" xyz="0 0 0" />
            <geometry>
                <mesh filename="package://robotiq_2f_140_gripper_visualization/meshes/visual/robotiq_arg2f_140_inner_finger.stl" />
            </geometry>
            <material name="">
                <color rgba="0.1 0.1 0.1 1" />
            </material>
        </visual>
        <collision>
            <origin rpy="0 0 0" xyz="0 0 0" />
            <geometry>
                <mesh filename="package://robotiq_2f_140_gripper_visualization/meshes/collision/robotiq_arg2f_140_inner_finger.stl" />
            </geometry>
        </collision>
    </link>
    <link name="left_inner_finger_pad">
        <visual>
            <origin rpy="0 0 0" xyz="0 0 0" />
            <geometry>
                <box size="0.027 0.065 0.0075" />
            </geometry>
            <material name="">
                <color rgba="0.9 0.9 0.9 1" />
            </material>
        </visual>
        <collision>
            <origin rpy="0 0 0" xyz="0 0 0" />
            <geometry>
                <box size="0.03 0.07 0.0075" />
            </geometry>
            <material name="">
                <color rgba="0.9 0.0 0.0 1" />
            </material>
        </collision>
        <inertial>
            <mass value="0.1" />
            <origin xyz="0 0 0" rpy="0 0 0" />
            <inertia ixx="0.03" iyy="0.03" izz="0.03" ixy="0.0" ixz="0.0" iyz="0.0" />
        </inertial>
    </link>
    <link name="left_inner_knuckle">
        <inertial>
            <origin rpy="0 0 0" xyz="0.000123011831763771 0.0507850843201817 0.00103968640075166" />
            <mass value="0.0271177346495152" />
            <inertia ixx="2.61910379223783E-05" ixy="-2.43616858946494E-07" ixz="-6.37789906117123E-09" iyy="2.8270243746167E-06" iyz="-5.37200748039765E-07" izz="2.83695868220296E-05" />
        </inertial>
        <visual>
            <origin rpy="0 0 0" xyz="0 0 0" />
            <geometry>
                <mesh filename="package://robotiq_2f_140_gripper_visualization/meshes/visual/robotiq_arg2f_140_inner_knuckle.stl" />
            </geometry>
            <material name="">
                <color rgba="0.1 0.1 0.1 1" />
            </material>
        </visual>
        <collision>
            <origin rpy="0 0 0" xyz="0 0 0" />
            <geometry>
                <mesh filename="package://robotiq_2f_140_gripper_visualization/meshes/collision/robotiq_arg2f_140_inner_knuckle.stl" />
            </geometry>
        </collision>
    </link>
    <joint name="left_outer_finger_joint" type="fixed">
        <origin rpy="0 0 0" xyz="0 0.01821998610742 0.0260018192872234" />
        <parent link="left_outer_knuckle" />
        <child link="left_outer_finger" />
        <axis xyz="1 0 0" />
    </joint>
    <joint name="left_inner_knuckle_joint" type="revolute">
        <origin rpy="2.2957963267948966 0 0.0" xyz="0 -0.0127 0.06142" />
        <parent link="robotiq_arg2f_base_link" />
        <child link="left_inner_knuckle" />
        <axis xyz="1 0 0" />
        <limit effort="1000" lower="-0.8757" upper="0" velocity="0.5" />
        <mimic joint="finger_joint" multiplier="-1" offset="0" />
    </joint>
    <joint name="left_inner_finger_joint" type="revolute">
        <origin rpy="-0.725 0 0" xyz="0 0.0817554015893473 -0.0282203446692936" />
        <parent link="left_outer_finger" />
        <child link="left_inner_finger" />
        <axis xyz="1 0 0" />
        <limit effort="1000" lower="0" upper="0.8757" velocity="0.5" />
        <mimic joint="finger_joint" multiplier="1" offset="0" />
    </joint>
    <joint name="left_inner_finger_pad_joint" type="fixed">
        <origin rpy="0 0 0" xyz="0 0.0457554015893473 -0.0272203446692936" />
        <parent link="left_inner_finger" />
        <child link="left_inner_finger_pad" />
        <axis xyz="0 0 1" />
    </joint>
    <joint name="finger_joint" type="revolute">
        <origin rpy="2.2957963267948966 0 0" xyz="0 -0.0306011 0.054904" />
        <parent link="robotiq_arg2f_base_link" />
        <child link="left_outer_knuckle" />
        <axis xyz="-1 0 0" />
        <limit effort="1000" lower="0" upper="0.7" velocity="0.5" />
    </joint>
    <joint name="right_outer_finger_joint" type="fixed">
        <origin rpy="0 0 0" xyz="0 0.01821998610742 0.0260018192872234" />
        <parent link="right_outer_knuckle" />
        <child link="right_outer_finger" />
        <axis xyz="1 0 0" />
    </joint>
    <joint name="right_inner_knuckle_joint" type="revolute">
        <origin rpy="2.2957963267948966 0 -3.141592653589793" xyz="0 0.0127 0.06142" />
        <parent link="robotiq_arg2f_base_link" />
        <child link="right_inner_knuckle" />
        <axis xyz="1 0 0" />
        <limit effort="1000" lower="-0.8757" upper="0" velocity="0.5" />
        <mimic joint="finger_joint" multiplier="-1" offset="0" />
    </joint>
    <joint name="right_inner_finger_joint" type="revolute">
        <origin rpy="-0.725 0 0" xyz="0 0.0817554015893473 -0.0282203446692936" />
        <parent link="right_outer_finger" />
        <child link="right_inner_finger" />
        <axis xyz="1 0 0" />
        <limit effort="1000" lower="0" upper="0.8757" velocity="0.5" />
        <mimic joint="finger_joint" multiplier="1" offset="0" />
    </joint>
    <joint name="right_inner_finger_pad_joint" type="fixed">
        <origin rpy="0 0 0" xyz="0 0.0457554015893473 -0.0272203446692936" />
        <parent link="right_inner_finger" />
        <child link="right_inner_finger_pad" />
        <axis xyz="0 0 1" />
    </joint>
    <link name="right_outer_knuckle">
        <inertial>
            <origin rpy="0 0 0" xyz="-0.000200000000003065 0.0199435877845359 0.0292245259211331" />
            <mass value="0.00853198276973456" />
            <inertia ixx="2.89328108496468E-06" ixy="-1.57935047237397E-19" ixz="-1.93980378593255E-19" iyy="1.86719750325683E-06" iyz="-1.21858577871576E-06" izz="1.21905238907251E-06" />
        </inertial>
        <visual>
            <origin rpy="0 0 0" xyz="0 0 0" />
            <geometry>
                <mesh filename="package://robotiq_2f_140_gripper_visualization/meshes/visual/robotiq_arg2f_140_outer_knuckle.stl" />
            </geometry>
            <material name="">
                <color rgba="0.792156862745098 0.819607843137255 0.933333333333333 1" />
            </material>
        </visual>
        <collision>
            <origin rpy="0 0 0" xyz="0 0 0" />
            <geometry>
                <mesh filename="package://robotiq_2f_140_gripper_visualization/meshes/collision/robotiq_arg2f_140_outer_knuckle.stl" />
            </geometry>
        </collision>
    </link>
    <link name="right_outer_finger">
        <inertial>
            <origin rpy="0 0 0" xyz="0.00030115855001899 0.0373907951953854 -0.0208027427000385" />
            <mass value="0.022614240507152" />
            <inertia ixx="1.52518312458174E-05" ixy="9.76583423954399E-10" ixz="-5.43838577022588E-10" iyy="6.17694243867776E-06" iyz="6.78636130740228E-06" izz="1.16494917907219E-05" />
        </inertial>
        <visual>
            <origin rpy="0 0 0" xyz="0 0 0" />
            <geometry>
                <mesh filename="package://robotiq_2f_140_gripper_visualization/meshes/visual/robotiq_arg2f_140_outer_finger.stl" />
            </geometry>
            <material name="">
                <color rgba="0.1 0.1 0.1 1" />
            </material>
        </visual>
        <collision>
            <origin rpy="0 0 0" xyz="0 0 0" />
            <geometry>
                <mesh filename="package://robotiq_2f_140_gripper_visualization/meshes/collision/robotiq_arg2f_140_outer_finger.stl" />
            </geometry>
        </collision>
    </link>
    <link name="right_inner_finger">
        <inertial>
            <origin rpy="0 0 0" xyz="0.000299999999999317 0.0160078233491243 -0.0136945669206257" />
            <mass value="0.0104003125914103" />
            <inertia ixx="2.71909453810972E-06" ixy="1.35402465472579E-21" ixz="-7.1817349065269E-22" iyy="7.69100314106116E-07" iyz="6.74715432769696E-07" izz="2.30315190420171E-06" />
        </inertial>
        <visual>
            <origin rpy="0 0 0" xyz="0 0 0" />
            <geometry>
                <mesh filename="package://robotiq_2f_140_gripper_visualization/meshes/visual/robotiq_arg2f_140_inner_finger.stl" />
            </geometry>
            <material name="">
                <color rgba="0.1 0.1 0.1 1" />
            </material>
        </visual>
        <collision>
            <origin rpy="0 0 0" xyz="0 0 0" />
            <geometry>
                <mesh filename="package://robotiq_2f_140_gripper_visualization/meshes/collision/robotiq_arg2f_140_inner_finger.stl" />
            </geometry>
        </collision>
    </link>
    <link name="right_inner_finger_pad">
        <visual>
            <origin rpy="0 0 0" xyz="0 0 0" />
            <geometry>
                <box size="0.027 0.065 0.0075" />
            </geometry>
            <material name="">
                <color rgba="0.9 0.9 0.9 1" />
            </material>
        </visual>
        <collision>
            <origin rpy="0 0 0" xyz="0 0 0" />
            <geometry>
                <box size="0.03 0.07 0.0075" />
            </geometry>
            <material name="">
                <color rgba="0.9 0.0 0.0 1" />
            </material>
        </collision>
        <inertial>
            <mass value="0.1" />
            <origin xyz="0 0 0" rpy="0 0 0" />
            <inertia ixx="0.03" iyy="0.03" izz="0.03" ixy="0.0" ixz="0.0" iyz="0.0" />
        </inertial>
    </link>
    <link name="right_inner_knuckle">
        <inertial>
            <origin rpy="0 0 0" xyz="0.000123011831763771 0.0507850843201817 0.00103968640075166" />
            <mass value="0.0271177346495152" />
            <inertia ixx="2.61910379223783E-05" ixy="-2.43616858946494E-07" ixz="-6.37789906117123E-09" iyy="2.8270243746167E-06" iyz="-5.37200748039765E-07" izz="2.83695868220296E-05" />
        </inertial>
        <visual>
            <origin rpy="0 0 0" xyz="0 0 0" />
            <geometry>
                <mesh filename="package://robotiq_2f_140_gripper_visualization/meshes/visual/robotiq_arg2f_140_inner_knuckle.stl" />
            </geometry>
            <material name="">
                <color rgba="0.1 0.1 0.1 1" />
            </material>
        </visual>
        <collision>
            <origin rpy="0 0 0" xyz="0 0 0" />
            <geometry>
                <mesh filename="package://robotiq_2f_140_gripper_visualization/meshes/collision/robotiq_arg2f_140_inner_knuckle.stl" />
            </geometry>
        </collision>
    </link>
    <joint name="right_finger_joint" type="revolute">
        <origin rpy="2.2957963267948966 0 3.141592653589793" xyz="0 0.0306011 0.054904" />
        <parent link="robotiq_arg2f_base_link" />
        <child link="right_outer_knuckle" />
        <axis xyz="1 0 0" />
        <limit effort="1000" lower="-0.725" upper="0" velocity="0.5" />
        <mimic joint="finger_joint" multiplier="-1" offset="0" />
    </joint>
    <!-- mount the fts to the robot -->
    <joint name="ft300_fix" type="fixed">
        <origin rpy="0 0 0" xyz="0 0 0" />
        <parent link="tool0" />
        <child link="ft300_mounting_plate" />
    </joint>
    <!-- Link representing the FT300 force-torque sensor -->
    <link name="ft300_sensor">
        <inertial>
            <origin rpy="0 0 0" xyz="0 0 -0.017" />
            <mass value="0.300" />
            <inertia ixx="0.000262" ixy="0" ixz="1e-06" iyx="0" iyy="0.000265" iyz="1e-06" izx="-1e-06" izy="1e-06" izz="0.000219" />
        </inertial>
        <visual>
            <origin rpy="0 0 0" xyz="0 0 0" />
            <geometry>
                <mesh filename="package://robotiq_ft_sensor/meshes/visual/robotiq_ft300.STL" />
            </geometry>
            <material name="Robotiq-Black">
                <color rgba="0.2 0.2 0.2 1.0" />
            </material>
        </visual>
        <collision>
            <origin rpy="0 0 0" xyz="0 0 0" />
            <geometry>
                <mesh filename="package://robotiq_ft_sensor/meshes/collision/robotiq_ft300.STL" />
            </geometry>
        </collision>
    </link>
    <!-- Link representing the FT300 mounting plate -->
    <link name="ft300_mounting_plate">
        <visual>
            <origin rpy="0 0 0" xyz="0 0 0" />
            <geometry>
                <mesh filename="package://robotiq_ft_sensor/meshes/visual/mountings/robotiq_ft300-G-062-COUPLING_G-50-4M6-1D6_20181119.STL" />
            </geometry>
            <material name="Robotiq-Grey">
                <color rgba="0.4 0.4 0.4 1.0" />
            </material>
        </visual>
        <collision>
            <origin rpy="0 0 0" xyz="0 0 0" />
            <geometry>
                <mesh filename="package://robotiq_ft_sensor/meshes/collision/mountings/robotiq_ft300-G-062-COUPLING_G-50-4M6-1D6_20181119.STL" />
            </geometry>
        </collision>
        <inertial>
            <mass value="0.1" />
            <origin xyz="0 0 0" rpy="0 0 0" />
            <inertia ixx="0.03" iyy="0.03" izz="0.03" ixy="0.0" ixz="0.0" iyz="0.0" />
        </inertial>
    </link>
    <!-- Connect force sensor with mounting/coupling plate -->
    <joint name="ft300_mounting_plate" type="fixed">
        <origin rpy="0 3.141592653589793 0" xyz="0 0 0.0415" />
        <parent link="ft300_mounting_plate" />
        <child link="ft300_sensor" />
    </joint>
    <!-- FORCE REFERENCE FRAME _______________________________________________________________________________
            As specified in the documentation:
            - The Z axis passes through the center of the depression with positive direction in the tool direction.
            - The X axis traces a symmetric line centered on the connector; the positive direction
                points the opposite way away from the connector.
            - The Y axis uses the right hand thumb rule according to X-Z. -->
    <joint name="measurment_joint" type="fixed">
        <origin rpy="0 3.141592653589793 -1.5707963267948966" xyz="0 0 0" />
        <parent link="ft300_sensor" />
        <child link="robotiq_ft_frame_id" />
    </joint>
    <link name="robotiq_ft_frame_id" />
    <!--robotiq_arg2f_140.xacro已经调用了robotiq_arg2f_140宏定义，这里只需要把gripper和sensor用joint连接起来即可-->
    <joint name="ft_gripper_joint" type="fixed">
        <parent link="robotiq_ft_frame_id" />
        <child link="robotiq_arg2f_base_link" />
        <origin rpy="0 0 0" xyz="0 0 0" />
    </joint>
    <material name="aluminum">
        <color rgba="0.5 0.5 0.5 1" />
    </material>
    <material name="plastic">
        <color rgba="0.1 0.1 0.1 1" />
    </material>
    <!-- camera body, with origin at bottom screw mount -->
    <joint name="camera_joint" type="fixed">
        <origin rpy="0 1.57 0" xyz="0.4 0 1" />
        <parent link="base" />
        <child link="camera_bottom_screw_frame" />
    </joint>
    <link name="camera_bottom_screw_frame" />
    <joint name="camera_link_joint" type="fixed">
        <origin rpy="0 0 0" xyz="0.010600000000000002 0.0175 0.0125" />
        <parent link="camera_bottom_screw_frame" />
        <child link="camera_link" />
    </joint>
    <link name="camera_link">
        <visual>
            <!-- the mesh origin is at front plate in between the two infrared camera axes -->
            <origin rpy="1.5707963267948966 0 1.5707963267948966" xyz="0.0043 -0.0175 0" />
            <geometry>
                <mesh filename="package://realsense2_description/meshes/d435.dae" />
            </geometry>
        </visual>
        <collision>
            <origin rpy="0 0 0" xyz="0 -0.0175 0" />
            <geometry>
                <box size="0.02505 0.09 0.025" />
            </geometry>
        </collision>
        <inertial>
            <!-- The following are not reliable values, and should not be used for modeling -->
            <mass value="0.072" />
            <origin xyz="0 0 0" rpy="0 0 0" />
            <inertia ixx="0.003881243" ixy="0.0" ixz="0.0" iyy="0.000498940" iyz="0.0" izz="0.003879257" />
        </inertial>
    </link>
    <transmission name="trans_left_inner_knuckle_joint">
        <type>transmission_interface/SimpleTransmission</type>
        <joint name="left_inner_knuckle_joint">
            <hardwareInterface>hardware_interface/EffortJointInterface</hardwareInterface>
        </joint>
        <actuator name="left_inner_knuckle_joint_motor">
            <hardwareInterface>hardware_interface/EffortJointInterface</hardwareInterface>
            <mechanicalReduction>1</mechanicalReduction>
        </actuator>
    </transmission>
    <transmission name="trans_left_inner_finger_joint">
        <type>transmission_interface/SimpleTransmission</type>
        <joint name="left_inner_finger_joint">
            <hardwareInterface>hardware_interface/EffortJointInterface</hardwareInterface>
        </joint>
        <actuator name="left_inner_finger_joint_motor">
            <hardwareInterface>hardware_interface/EffortJointInterface</hardwareInterface>
            <mechanicalReduction>1</mechanicalReduction>
        </actuator>
    </transmission>
    <transmission name="trans_right_inner_knuckle_joint">
        <type>transmission_interface/SimpleTransmission</type>
        <joint name="right_inner_knuckle_joint">
            <hardwareInterface>hardware_interface/EffortJointInterface</hardwareInterface>
        </joint>
        <actuator name="right_inner_knuckle_joint_motor">
            <hardwareInterface>hardware_interface/EffortJointInterface</hardwareInterface>
            <mechanicalReduction>1</mechanicalReduction>
        </actuator>
    </transmission>
    <transmission name="trans_right_inner_finger_joint">
        <type>transmission_interface/SimpleTransmission</type>
        <joint name="right_inner_finger_joint">
            <hardwareInterface>hardware_interface/EffortJointInterface</hardwareInterface>
        </joint>
        <actuator name="right_inner_finger_joint_motor">
            <hardwareInterface>hardware_interface/EffortJointInterface</hardwareInterface>
            <mechanicalReduction>1</mechanicalReduction>
        </actuator>
    </transmission>
    <transmission name="trans_right_finger_joint">
        <type>transmission_interface/SimpleTransmission</type>
        <joint name="right_finger_joint">
            <hardwareInterface>hardware_interface/EffortJointInterface</hardwareInterface>
        </joint>
        <actuator name="right_finger_joint_motor">
            <hardwareInterface>hardware_interface/EffortJointInterface</hardwareInterface>
            <mechanicalReduction>1</mechanicalReduction>
        </actuator>
    </transmission>

    <gazebo>
        <plugin name="gazebo_ros_control" filename="libgazebo_ros_control.so">
            <robotNamespace>/</robotNamespace>
        </plugin>
    </gazebo>
</robot>

